---
title: Compiler-Fehler C2707 generiert | Microsoft Docs
ms.custom: 
ms.date: 11/04/2016
ms.reviewer: 
ms.suite: 
ms.technology: cpp-tools
ms.tgt_pltfrm: 
ms.topic: error-reference
f1_keywords: C2707
dev_langs: C++
helpviewer_keywords: C2707
ms.assetid: 3deaf45c-74da-4c9d-acc6-b82412720b74
caps.latest.revision: "9"
author: corob-msft
ms.author: corob
manager: ghogen
ms.workload: cplusplus
ms.openlocfilehash: 877ca1b0592625823e262f77f7f2adcfc5c04e3e
ms.sourcegitcommit: 8fa8fdf0fbb4f57950f1e8f4f9b81b4d39ec7d7a
ms.translationtype: MT
ms.contentlocale: de-DE
ms.lasthandoff: 12/21/2017
---
# <a name="compiler-error-c2707"></a>Compiler-Fehler C2707 generiert
'Bezeichner': Ungültiger Kontext für die systeminterne Funktion  
  
 Strukturierte Ausnahmebehandlung systeminternen Funktionen sind in bestimmten Kontexten ungültig:  
  
-   `_exception_code()`außerhalb eines Ausnahmefilters oder `__except` Block  
  
-   `_exception_info()`außerhalb eines Ausnahmefilters  
  
-   `_abnormal_termination()`außerhalb einer `__finally` Block  
  
 Um den Fehler zu beheben, achten Sie darauf, dass die Ausnahmebehandlung systeminternen Funktionen im entsprechenden Kontext platziert werden.  
  
## <a name="example"></a>Beispiel  
 Im folgende Beispiel wird C2707 generiert.  
  
```  
// C2707.cpp  
#include <windows.h>  
#include <stdio.h>  
  
LONG MyFilter(LONG excode)   
{  
    return (excode == EXCEPTION_ACCESS_VIOLATION ?  
        EXCEPTION_EXECUTE_HANDLER : EXCEPTION_CONTINUE_SEARCH);   // OK  
}  
  
LONG func(void)   
{  
    int x, y;  
    return(GetExceptionCode() == EXCEPTION_ACCESS_VIOLATION ?  // C2707  
             EXCEPTION_EXECUTE_HANDLER : EXCEPTION_CONTINUE_SEARCH);  
  
    __try   
    {  
        y = 0;  
        x = 4 / y;  
        return 0;  
     }  
  
    __except(MyFilter(GetExceptionCode()))   
    {  
        return(GetExceptionCode() == EXCEPTION_ACCESS_VIOLATION ? // ok  
               EXCEPTION_EXECUTE_HANDLER : EXCEPTION_CONTINUE_SEARCH);  
    }  
}  
  
int main()   
{  
    __try   
    {  
        func();  
    } __except(EXCEPTION_EXECUTE_HANDLER)  
    {  
        printf_s("Caught exception\n");  
    }  
}  
```